Workbook

Sheet 2026
A1: Week 1 | C1: Austin | D1: Carson | E1: Clayton | F1: Dan | G1: Hunter | H1: Jake | I1: Nick | J1: Tanner | K1: Taylon | L1: Trey | O1: Parlay
A3: Pick | N3: Odds | O3: =IF(AND(C4="",AND(D4="",AND(E4="",AND(F4="",AND(G4="",AND(H4="",AND(I4="",AND(J4="",AND(K4="",L4=""))))))))),"",IF(((IF(C4="",1,IF(C4>0,(C4/100)+1,(100/((-1)*C4))+1)))*(IF(D4="",1,IF(D4>0,(D4/100)+1,(100/((-1)*D4))+1)))*(IF(E4="",1,IF(E4>0,(E4/100)+1,(100/((-1)*E4))+1)))*(IF(F4="",1,IF(F4>0,(F4/100)+1,(100/((-1)*F4))+1)))*(IF(G4="",1,IF(G4>0,(G4/100)+1,(100/((-1)*G4))+1)))*(IF(H4="",1,IF(H4>0,(H4/100)+1,(100/((-1)*H4))+1)))*(IF(I4="",1,IF(I4>0,(I4/100)+1,(100/((-1)*I4))+1)))*(IF(J4="",1,IF(J4>0,(J4/100)+1,(100/((-1)*J4))+1)))*(IF(K4="",1,IF(K4>0,(K4/100)+1,(100/((-1)*K4))+1)))*(IF(L4="",1,IF(L4>0,(L4/100)+1,(100/((-1)*L4))+1))))<2,((-100)/(((IF(C4="",1,IF(C4>0,(C4/100)+1,(100/((-1)*C4))+1)))*(IF(D4="",1,IF(D4>0,(D4/100)+1,(100/((-1)*D4))+1)))*(IF(E4="",1,IF(E4>0,(E4/100)+1,(100/((-1)*E4))+1)))*(IF(F4="",1,IF(F4>0,(F4/100)+1,(100/((-1)*F4))+1)))*(IF(G4="",1,IF(G4>0,(G4/100)+1,(100/((-1)*G4))+1)))*(IF(H4="",1,IF(H4>0,(H4/100)+1,(100/((-1)*H4))+1)))*(IF(I4="",1,IF(I4>0,(I4/100)+1,(100/((-1)*I4))+1)))*(IF(J4="",1,IF(J4>0,(J4/100)+1,(100/((-1)*J4))+1)))*(IF(K4="",1,IF(K4>0,(K4/100)+1,(100/((-1)*K4))+1)))*(IF(L4="",1,IF(L4>0,(L4/100)+1,(100/((-1)*L4))+1))))-1)),((((IF(C4="",1,IF(C4>0,(C4/100)+1,(100/((-1)*C4))+1)))*(IF(D4="",1,IF(D4>0,(D4/100)+1,(100/((-1)*D4))+1)))*(IF(E4="",1,IF(E4>0,(E4/100)+1,(100/((-1)*E4))+1)))*(IF(F4="",1,IF(F4>0,(F4/100)+1,(100/((-1)*F4))+1)))*(IF(G4="",1,IF(G4>0,(G4/100)+1,(100/((-1)*G4))+1)))*(IF(H4="",1,IF(H4>0,(H4/100)+1,(100/((-1)*H4))+1)))*(IF(I4="",1,IF(I4>0,(I4/100)+1,(100/((-1)*I4))+1)))*(IF(J4="",1,IF(J4>0,(J4/100)+1,(100/((-1)*J4))+1)))*(IF(K4="",1,IF(K4>0,(K4/100)+1,(100/((-1)*K4))+1)))*(IF(L4="",1,IF(L4>0,(L4/100)+1,(100/((-1)*L4))+1))))-1)*(100)))) | Q3: *Pick Made For Me*
A4: Odds | N4: Return | O4: =IF(AND(C4="",AND(D4="",AND(E4="",AND(F4="",AND(G4="",AND(H4="",AND(I4="",AND(J4="",AND(K4="",L4=""))))))))),"",10+IF((IF(((IF(C4="",1,IF(C4>0,(C4/100)+1,(100/((-1)*C4))+1)))*(IF(D4="",1,IF(D4>0,(D4/100)+1,(100/((-1)*D4))+1)))*(IF(E4="",1,IF(E4>0,(E4/100)+1,(100/((-1)*E4))+1)))*(IF(F4="",1,IF(F4>0,(F4/100)+1,(100/((-1)*F4))+1)))*(IF(G4="",1,IF(G4>0,(G4/100)+1,(100/((-1)*G4))+1)))*(IF(H4="",1,IF(H4>0,(H4/100)+1,(100/((-1)*H4))+1)))*(IF(I4="",1,IF(I4>0,(I4/100)+1,(100/((-1)*I4))+1)))*(IF(J4="",1,IF(J4>0,(J4/100)+1,(100/((-1)*J4))+1)))*(IF(K4="",1,IF(K4>0,(K4/100)+1,(100/((-1)*K4))+1)))*(IF(L4="",1,IF(L4>0,(L4/100)+1,(100/((-1)*L4))+1))))<2,((-100)/(((IF(C4="",1,IF(C4>0,(C4/100)+1,(100/((-1)*C4))+1)))*(IF(D4="",1,IF(D4>0,(D4/100)+1,(100/((-1)*D4))+1)))*(IF(E4="",1,IF(E4>0,(E4/100)+1,(100/((-1)*E4))+1)))*(IF(F4="",1,IF(F4>0,(F4/100)+1,(100/((-1)*F4))+1)))*(IF(G4="",1,IF(G4>0,(G4/100)+1,(100/((-1)*G4))+1)))*(IF(H4="",1,IF(H4>0,(H4/100)+1,(100/((-1)*H4))+1)))*(IF(I4="",1,IF(I4>0,(I4/100)+1,(100/((-1)*I4))+1)))*(IF(J4="",1,IF(J4>0,(J4/100)+1,(100/((-1)*J4))+1)))*(IF(K4="",1,IF(K4>0,(K4/100)+1,(100/((-1)*K4))+1)))*(IF(L4="",1,IF(L4>0,(L4/100)+1,(100/((-1)*L4))+1))))-1)),((((IF(C4="",1,IF(C4>0,(C4/100)+1,(100/((-1)*C4))+1)))*(IF(D4="",1,IF(D4>0,(D4/100)+1,(100/((-1)*D4))+1)))*(IF(E4="",1,IF(E4>0,(E4/100)+1,(100/((-1)*E4))+1)))*(IF(F4="",1,IF(F4>0,(F4/100)+1,(100/((-1)*F4))+1)))*(IF(G4="",1,IF(G4>0,(G4/100)+1,(100/((-1)*G4))+1)))*(IF(H4="",1,IF(H4>0,(H4/100)+1,(100/((-1)*H4))+1)))*(IF(I4="",1,IF(I4>0,(I4/100)+1,(100/((-1)*I4))+1)))*(IF(J4="",1,IF(J4>0,(J4/100)+1,(100/((-1)*J4))+1)))*(IF(K4="",1,IF(K4>0,(K4/100)+1,(100/((-1)*K4))+1)))*(IF(L4="",1,IF(L4>0,(L4/100)+1,(100/((-1)*L4))+1))))-1)*(100))))<0,(((-100)/((IF(((IF(C4="",1,IF(C4>0,(C4/100)+1,(100/((-1)*C4))+1)))*(IF(D4="",1,IF(D4>0,(D4/100)+1,(100/((-1)*D4))+1)))*(IF(E4="",1,IF(E4>0,(E4/100)+1,(100/((-1)*E4))+1)))*(IF(F4="",1,IF(F4>0,(F4/100)+1,(100/((-1)*F4))+1)))*(IF(G4="",1,IF(G4>0,(G4/100)+1,(100/((-1)*G4))+1)))*(IF(H4="",1,IF(H4>0,(H4/100)+1,(100/((-1)*H4))+1)))*(IF(I4="",1,IF(I4>0,(I4/100)+1,(100/((-1)*I4))+1)))*(IF(J4="",1,IF(J4>0,(J4/100)+1,(100/((-1)*J4))+1)))*(IF(K4="",1,IF(K4>0,(K4/100)+1,(100/((-1)*K4))+1)))*(IF(L4="",1,IF(L4>0,(L4/100)+1,(100/((-1)*L4))+1))))<2,((-100)/(((IF(C4="",1,IF(C4>0,(C4/100)+1,(100/((-1)*C4))+1)))*(IF(D4="",1,IF(D4>0,(D4/100)+1,(100/((-1)*D4))+1)))*(IF(E4="",1,IF(E4>0,(E4/100)+1,(100/((-1)*E4))+1)))*(IF(F4="",1,IF(F4>0,(F4/100)+1,(100/((-1)*F4))+1)))*(IF(G4="",1,IF(G4>0,(G4/100)+1,(100/((-1)*G4))+1)))*(IF(H4="",1,IF(H4>0,(H4/100)+1,(100/((-1)*H4))+1)))*(IF(I4="",1,IF(I4>0,(I4/100)+1,(100/((-1)*I4))+1)))*(IF(J4="",1,IF(J4>0,(J4/100)+1,(100/((-1)*J4))+1)))*(IF(K4="",1,IF(K4>0,(K4/100)+1,(100/((-1)*K4))+1)))*(IF(L4="",1,IF(L4>0,(L4/100)+1,(100/((-1)*L4))+1))))-1)),((((IF(C4="",1,IF(C4>0,(C4/100)+1,(100/((-1)*C4))+1)))*(IF(D4="",1,IF(D4>0,(D4/100)+1,(100/((-1)*D4))+1)))*(IF(E4="",1,IF(E4>0,(E4/100)+1,(100/((-1)*E4))+1)))*(IF(F4="",1,IF(F4>0,(F4/100)+1,(100/((-1)*F4))+1)))*(IF(G4="",1,IF(G4>0,(G4/100)+1,(100/((-1)*G4))+1)))*(IF(H4="",1,IF(H4>0,(H4/100)+1,(100/((-1)*H4))+1)))*(IF(I4="",1,IF(I4>0,(I4/100)+1,(100/((-1)*I4))+1)))*(IF(J4="",1,IF(J4>0,(J4/100)+1,(100/((-1)*J4))+1)))*(IF(K4="",1,IF(K4>0,(K4/100)+1,(100/((-1)*K4))+1)))*(IF(L4="",1,IF(L4>0,(L4/100)+1,(100/((-1)*L4))+1))))-1)*(100))))))*10),(((IF(((IF(C4="",1,IF(C4>0,(C4/100)+1,(100/((-1)*C4))+1)))*(IF(D4="",1,IF(D4>0,(D4/100)+1,(100/((-1)*D4))+1)))*(IF(E4="",1,IF(E4>0,(E4/100)+1,(100/((-1)*E4))+1)))*(IF(F4="",1,IF(F4>0,(F4/100)+1,(100/((-1)*F4))+1)))*(IF(G4="",1,IF(G4>0,(G4/100)+1,(100/((-1)*G4))+1)))*(IF(H4="",1,IF(H4>0,(H4/100)+1,(100/((-1)*H4))+1)))*(IF(I4="",1,IF(I4>0,(I4/100)+1,(100/((-1)*I4))+1)))*(IF(J4="",1,IF(J4>0,(J4/100)+1,(100/((-1)*J4))+1)))*(IF(K4="",1,IF(K4>0,(K4/100)+1,(100/((-1)*K4))+1)))*(IF(L4="",1,IF(L4>0,(L4/100)+1,(100/((-1)*L4))+1))))<2,((-100)/(((IF(C4="",1,IF(C4>0,(C4/100)+1,(100/((-1)*C4))+1)))*(IF(D4="",1,IF(D4>0,(D4/100)+1,(100/((-1)*D4))+1)))*(IF(E4="",1,IF(E4>0,(E4/100)+1,(100/((-1)*E4))+1)))*(IF(F4="",1,IF(F4>0,(F4/100)+1,(100/((-1)*F4))+1)))*(IF(G4="",1,IF(G4>0,(G4/100)+1,(100/((-1)*G4))+1)))*(IF(H4="",1,IF(H4>0,(H4/100)+1,(100/((-1)*H4))+1)))*(IF(I4="",1,IF(I4>0,(I4/100)+1,(100/((-1)*I4))+1)))*(IF(J4="",1,IF(J4>0,(J4/100)+1,(100/((-1)*J4))+1)))*(IF(K4="",1,IF(K4>0,(K4/100)+1,(100/((-1)*K4))+1)))*(IF(L4="",1,IF(L4>0,(L4/100)+1,(100/((-1)*L4))+1))))-1)),((((IF(C4="",1,IF(C4>0,(C4/100)+1,(100/((-1)*C4))+1)))*(IF(D4="",1,IF(D4>0,(D4/100)+1,(100/((-1)*D4))+1)))*(IF(E4="",1,IF(E4>0,(E4/100)+1,(100/((-1)*E4))+1)))*(IF(F4="",1,IF(F4>0,(F4/100)+1,(100/((-1)*F4))+1)))*(IF(G4="",1,IF(G4>0,(G4/100)+1,(100/((-1)*G4))+1)))*(IF(H4="",1,IF(H4>0,(H4/100)+1,(100/((-1)*H4))+1)))*(IF(I4="",1,IF(I4>0,(I4/100)+1,(100/((-1)*I4))+1)))*(IF(J4="",1,IF(J4>0,(J4/100)+1,(100/((-1)*J4))+1)))*(IF(K4="",1,IF(K4>0,(K4/100)+1,(100/((-1)*K4))+1)))*(IF(L4="",1,IF(L4>0,(L4/100)+1,(100/((-1)*L4))+1))))-1)*(100))))/100)*10)))
A5: Matchup
A6: Outcome | O6: This Week | P6: Cumulative
A7: W/L | N7: Best Handicapper | O7: =IFERROR(__xludf.DUMMYFUNCTION("IF(OR(COUNTA(C4:L4) = 0, COUNTA(C7:L7) = 0), """", IFERROR(TEXTJOIN("", "", TRUE, FILTER(C1:L1, (C7:L7 = ""W"") * (C4:L4 = MAX(FILTER(C4:L4, C7:L7 = ""W""))))), """"))"),"") | P7: =IFERROR(__xludf.DUMMYFUNCTION("IF(COUNTA(C12:L12) = 0, """", IFERROR(TEXTJOIN("", "", TRUE, FILTER(C1:L1, C12:L12 = MAX(C12:L12))), """"))"),"")
A8: Wins | C8: =IF(C7="","",COUNTIF(C7,"W")) | D8: =IF(D7="","",COUNTIF(D7,"W")) | E8: =IF(E7="","",COUNTIF(E7,"W")) | F8: =IF(F7="","",COUNTIF(F7,"W")) | G8: =IF(G7="","",COUNTIF(G7,"W")) | H8: =IF(H7="","",COUNTIF(H7,"W")) | I8: =IF(I7="","",COUNTIF(I7,"W")) | J8: =IF(J7="","",COUNTIF(J7,"W")) | ... L8: =IF(L7="","",COUNTIF(L7,"W")) | N8: Worst Handicapper | O8: =IFERROR(__xludf.DUMMYFUNCTION("IF(OR(COUNTA(C4:L4) = 0, COUNTA(C7:L7) = 0), """", IFERROR(TEXTJOIN("", "", TRUE, FILTER(C1:L1, (C7:L7 = ""L"") * (C4:L4 = MIN(FILTER(C4:L4, C7:L7 = ""L""))))), """"))"),"") | P8: =IFERROR(__xludf.DUMMYFUNCTION("IF(COUNTA(C12:L12) = 0, """", IFERROR(TEXTJOIN("", "", TRUE, FILTER(C1:L1, C12:L12 = MIN(C12:L12))), """"))"),"")
A9: Losses | C9: =IF(C7="","",COUNTIF(C7,"L")) | D9: =IF(D7="","",COUNTIF(D7,"L")) | E9: =IF(E7="","",COUNTIF(E7,"L")) | F9: =IF(F7="","",COUNTIF(F7,"L")) | G9: =IF(G7="","",COUNTIF(G7,"L")) | H9: =IF(H7="","",COUNTIF(H7,"L")) | I9: =IF(I7="","",COUNTIF(I7,"L")) | J9: =IF(J7="","",COUNTIF(J7,"L")) | ... L9: =IF(L7="","",COUNTIF(L7,"L")) | N9: Ballsiest Bettor | O9: =IFERROR(__xludf.DUMMYFUNCTION("IF(COUNTA(C4:L4) = 0, """", IFERROR(TEXTJOIN("", "", TRUE, FILTER(C1:L1, C4:L4 = MAX(C4:L4))), """"))"),"") | P9: =IFERROR(__xludf.DUMMYFUNCTION("IF(COUNTA(C4:L4) = 0, """", IFERROR(TEXTJOIN("", "", TRUE, FILTER(C1:L1, C11:L11 = MAX(C11:L11))), """"))"),"")
A10: Win % | C10: =IF(C7="","",(C8/(C8+C9))) | D10: =IF(D7="","",(D8/(D8+D9))) | E10: =IF(E7="","",(E8/(E8+E9))) | F10: =IF(F7="","",(F8/(F8+F9))) | G10: =IF(G7="","",(G8/(G8+G9))) | H10: =IF(H7="","",(H8/(H8+H9))) | I10: =IF(I7="","",(I8/(I8+I9))) | J10: =IF(J7="","",(J8/(J8+J9))) | ... L10: =IF(L7="","",(L8/(L8+L9))) | N10: Parlay Pussy | O10: =IFERROR(__xludf.DUMMYFUNCTION("IF(COUNTA(C4:L4) = 0, """", IFERROR(TEXTJOIN("", "", TRUE, FILTER(C1:L1, C4:L4 = MIN(C4:L4))), """"))"),"") | P10: =IFERROR(__xludf.DUMMYFUNCTION("IF(COUNTA(C4:L4) = 0, """", IFERROR(TEXTJOIN("", "", TRUE, FILTER(C1:L1, C11:L11 = MIN(C11:L11))), """"))"),"")
A11: Average Odds | C11: =C4 | D11: =D4 | E11: =E4 | F11: =F4 | G11: =G4 | H11: =H4 | I11: =I4 | J11: =J4 | ... L11: =L4
A12: "If I bet $10 every week" | C12: =IFERROR(__xludf.DUMMYFUNCTION("IF(C7="""","""",IF(REGEXMATCH(C7,""W""),IF(C4<0,((-100/C4))*10,((C4/100)*10)),-10))"),"") | D12: =IFERROR(__xludf.DUMMYFUNCTION("IF(D7="""","""",IF(REGEXMATCH(D7,""W""),IF(D4<0,((-100/D4))*10,((D4/100)*10)),-10))"),"") | E12: =IFERROR(__xludf.DUMMYFUNCTION("IF(E7="""","""",IF(REGEXMATCH(E7,""W""),IF(E4<0,((-100/E4))*10,((E4/100)*10)),-10))"),"") | F12: =IFERROR(__xludf.DUMMYFUNCTION("IF(F7="""","""",IF(REGEXMATCH(F7,""W""),IF(F4<0,((-100/F4))*10,((F4/100)*10)),-10))"),"") | G12: =IFERROR(__xludf.DUMMYFUNCTION("IF(G7="""","""",IF(REGEXMATCH(G7,""W""),IF(G4<0,((-100/G4))*10,((G4/100)*10)),-10))"),"") | H12: =IFERROR(__xludf.DUMMYFUNCTION("IF(H7="""","""",IF(REGEXMATCH(H7,""W""),IF(H4<0,((-100/H4))*10,((H4/100)*10)),-10))"),"") | I12: =IFERROR(__xludf.DUMMYFUNCTION("IF(I7="""","""",IF(REGEXMATCH(I7,""W""),IF(I4<0,((-100/I4))*10,((I4/100)*10)),-10))"),"") | J12: =IFERROR(__xludf.DUMMYFUNCTION("IF(J7="""","""",IF(REGEXMATCH(J7,""W""),IF(J4<0,((-100/J4))*10,((J4/100)*10)),-10))"),"") | K12: =IFERROR(__xludf.DUMMYFUNCTION("IF(K7="""","""",IF(REGEXMATCH(K7,""W""),IF(K4<0,((-100/K4))*10,((K4/100)*10)),-10))"),"") | L12: =IFERROR(__xludf.DUMMYFUNCTION("IF(L7="""","""",IF(REGEXMATCH(L7,""W""),IF(L4<0,((-100/L4))*10,((L4/100)*10)),-10))"),"") | N12: "If I placed all 10 bets @ $10 each week" | O12: =sum(C12:L12) -> 0 | P12: =O12 -> 0
A14: Week 2 | C14: Austin | D14: Carson | E14: Clayton | F14: Dan | G14: Hunter | H14: Jake | I14: Nick | J14: Tanner | K14: Taylon | L14: Trey | O14: Parlay
A16: Pick | N16: Odds | O16: =IF(AND(C17="",AND(D17="",AND(E17="",AND(F17="",AND(G17="",AND(H17="",AND(I17="",AND(J17="",AND(K17="",L17=""))))))))),"",IF(((IF(C17="",1,IF(C17>0,(C17/100)+1,(100/((-1)*C17))+1)))*(IF(D17="",1,IF(D17>0,(D17/100)+1,(100/((-1)*D17))+1)))*(IF(E17="",1,IF(E17>0,(E17/100)+1,(100/((-1)*E17))+1)))*(IF(F17="",1,IF(F17>0,(F17/100)+1,(100/((-1)*F17))+1)))*(IF(G17="",1,IF(G17>0,(G17/100)+1,(100/((-1)*G17))+1)))*(IF(H17="",1,IF(H17>0,(H17/100)+1,(100/((-1)*H17))+1)))*(IF(I17="",1,IF(I17>0,(I17/100)+1,(100/((-1)*I17))+1)))*(IF(J17="",1,IF(J17>0,(J17/100)+1,(100/((-1)*J17))+1)))*(IF(K17="",1,IF(K17>0,(K17/100)+1,(100/((-1)*K17))+1)))*(IF(L17="",1,IF(L17>0,(L17/100)+1,(100/((-1)*L17))+1))))<2,((-100)/(((IF(C17="",1,IF(C17>0,(C17/100)+1,(100/((-1)*C17))+1)))*(IF(D17="",1,IF(D17>0,(D17/100)+1,(100/((-1)*D17))+1)))*(IF(E17="",1,IF(E17>0,(E17/100)+1,(100/((-1)*E17))+1)))*(IF(F17="",1,IF(F17>0,(F17/100)+1,(100/((-1)*F17))+1)))*(IF(G17="",1,IF(G17>0,(G17/100)+1,(100/((-1)*G17))+1)))*(IF(H17="",1,IF(H17>0,(H17/100)+1,(100/((-1)*H17))+1)))*(IF(I17="",1,IF(I17>0,(I17/100)+1,(100/((-1)*I17))+1)))*(IF(J17="",1,IF(J17>0,(J17/100)+1,(100/((-1)*J17))+1)))*(IF(K17="",1,IF(K17>0,(K17/100)+1,(100/((-1)*K17))+1)))*(IF(L17="",1,IF(L17>0,(L17/100)+1,(100/((-1)*L17))+1))))-1)),((((IF(C17="",1,IF(C17>0,(C17/100)+1,(100/((-1)*C17))+1)))*(IF(D17="",1,IF(D17>0,(D17/100)+1,(100/((-1)*D17))+1)))*(IF(E17="",1,IF(E17>0,(E17/100)+1,(100/((-1)*E17))+1)))*(IF(F17="",1,IF(F17>0,(F17/100)+1,(100/((-1)*F17))+1)))*(IF(G17="",1,IF(G17>0,(G17/100)+1,(100/((-1)*G17))+1)))*(IF(H17="",1,IF(H17>0,(H17/100)+1,(100/((-1)*H17))+1)))*(IF(I17="",1,IF(I17>0,(I17/100)+1,(100/((-1)*I17))+1)))*(IF(J17="",1,IF(J17>0,(J17/100)+1,(100/((-1)*J17))+1)))*(IF(K17="",1,IF(K17>0,(K17/100)+1,(100/((-1)*K17))+1)))*(IF(L17="",1,IF(L17>0,(L17/100)+1,(100/((-1)*L17))+1))))-1)*(100)))) | Q16: *Pick Made For Me*
A17: Odds | M17: 1 | N17: Return | O17: =IF(AND(C17="",AND(D17="",AND(E17="",AND(F17="",AND(G17="",AND(H17="",AND(I17="",AND(J17="",AND(K17="",L17=""))))))))),"",10+IF((IF(((IF(C17="",1,IF(C17>0,(C17/100)+1,(100/((-1)*C17))+1)))*(IF(D17="",1,IF(D17>0,(D17/100)+1,(100/((-1)*D17))+1)))*(IF(E17="",1,IF(E17>0,(E17/100)+1,(100/((-1)*E17))+1)))*(IF(F17="",1,IF(F17>0,(F17/100)+1,(100/((-1)*F17))+1)))*(IF(G17="",1,IF(G17>0,(G17/100)+1,(100/((-1)*G17))+1)))*(IF(H17="",1,IF(H17>0,(H17/100)+1,(100/((-1)*H17))+1)))*(IF(I17="",1,IF(I17>0,(I17/100)+1,(100/((-1)*I17))+1)))*(IF(J17="",1,IF(J17>0,(J17/100)+1,(100/((-1)*J17))+1)))*(IF(K17="",1,IF(K17>0,(K17/100)+1,(100/((-1)*K17))+1)))*(IF(L17="",1,IF(L17>0,(L17/100)+1,(100/((-1)*L17))+1))))<2,((-100)/(((IF(C17="",1,IF(C17>0,(C17/100)+1,(100/((-1)*C17))+1)))*(IF(D17="",1,IF(D17>0,(D17/100)+1,(100/((-1)*D17))+1)))*(IF(E17="",1,IF(E17>0,(E17/100)+1,(100/((-1)*E17))+1)))*(IF(F17="",1,IF(F17>0,(F17/100)+1,(100/((-1)*F17))+1)))*(IF(G17="",1,IF(G17>0,(G17/100)+1,(100/((-1)*G17))+1)))*(IF(H17="",1,IF(H17>0,(H17/100)+1,(100/((-1)*H17))+1)))*(IF(I17="",1,IF(I17>0,(I17/100)+1,(100/((-1)*I17))+1)))*(IF(J17="",1,IF(J17>0,(J17/100)+1,(100/((-1)*J17))+1)))*(IF(K17="",1,IF(K17>0,(K17/100)+1,(100/((-1)*K17))+1)))*(IF(L17="",1,IF(L17>0,(L17/100)+1,(100/((-1)*L17))+1))))-1)),((((IF(C17="",1,IF(C17>0,(C17/100)+1,(100/((-1)*C17))+1)))*(IF(D17="",1,IF(D17>0,(D17/100)+1,(100/((-1)*D17))+1)))*(IF(E17="",1,IF(E17>0,(E17/100)+1,(100/((-1)*E17))+1)))*(IF(F17="",1,IF(F17>0,(F17/100)+1,(100/((-1)*F17))+1)))*(IF(G17="",1,IF(G17>0,(G17/100)+1,(100/((-1)*G17))+1)))*(IF(H17="",1,IF(H17>0,(H17/100)+1,(100/((-1)*H17))+1)))*(IF(I17="",1,IF(I17>0,(I17/100)+1,(100/((-1)*I17))+1)))*(IF(J17="",1,IF(J17>0,(J17/100)+1,(100/((-1)*J17))+1)))*(IF(K17="",1,IF(K17>0,(K17/100)+1,(100/((-1)*K17))+1)))*(IF(L17="",1,IF(L17>0,(L17/100)+1,(100/((-1)*L17))+1))))-1)*(100))))<0,(((-100)/((IF(((IF(C17="",1,IF(C17>0,(C17/100)+1,(100/((-1)*C17))+1)))*(IF(D17="",1,IF(D17>0,(D17/100)+1,(100/((-1)*D17))+1)))*(IF(E17="",1,IF(E17>0,(E17/100)+1,(100/((-1)*E17))+1)))*(IF(F17="",1,IF(F17>0,(F17/100)+1,(100/((-1)*F17))+1)))*(IF(G17="",1,IF(G17>0,(G17/100)+1,(100/((-1)*G17))+1)))*(IF(H17="",1,IF(H17>0,(H17/100)+1,(100/((-1)*H17))+1)))*(IF(I17="",1,IF(I17>0,(I17/100)+1,(100/((-1)*I17))+1)))*(IF(J17="",1,IF(J17>0,(J17/100)+1,(100/((-1)*J17))+1)))*(IF(K17="",1,IF(K17>0,(K17/100)+1,(100/((-1)*K17))+1)))*(IF(L17="",1,IF(L17>0,(L17/100)+1,(100/((-1)*L17))+1))))<2,((-100)/(((IF(C17="",1,IF(C17>0,(C17/100)+1,(100/((-1)*C17))+1)))*(IF(D17="",1,IF(D17>0,(D17/100)+1,(100/((-1)*D17))+1)))*(IF(E17="",1,IF(E17>0,(E17/100)+1,(100/((-1)*E17))+1)))*(IF(F17="",1,IF(F17>0,(F17/100)+1,(100/((-1)*F17))+1)))*(IF(G17="",1,IF(G17>0,(G17/100)+1,(100/((-1)*G17))+1)))*(IF(H17="",1,IF(H17>0,(H17/100)+1,(100/((-1)*H17))+1)))*(IF(I17="",1,IF(I17>0,(I17/100)+1,(100/((-1)*I17))+1)))*(IF(J17="",1,IF(J17>0,(J17/100)+1,(100/((-1)*J17))+1)))*(IF(K17="",1,IF(K17>0,(K17/100)+1,(100/((-1)*K17))+1)))*(IF(L17="",1,IF(L17>0,(L17/100)+1,(100/((-1)*L17))+1))))-1)),((((IF(C17="",1,IF(C17>0,(C17/100)+1,(100/((-1)*C17))+1)))*(IF(D17="",1,IF(D17>0,(D17/100)+1,(100/((-1)*D17))+1)))*(IF(E17="",1,IF(E17>0,(E17/100)+1,(100/((-1)*E17))+1)))*(IF(F17="",1,IF(F17>0,(F17/100)+1,(100/((-1)*F17))+1)))*(IF(G17="",1,IF(G17>0,(G17/100)+1,(100/((-1)*G17))+1)))*(IF(H17="",1,IF(H17>0,(H17/100)+1,(100/((-1)*H17))+1)))*(IF(I17="",1,IF(I17>0,(I17/100)+1,(100/((-1)*I17))+1)))*(IF(J17="",1,IF(J17>0,(J17/100)+1,(100/((-1)*J17))+1)))*(IF(K17="",1,IF(K17>0,(K17/100)+1,(100/((-1)*K17))+1)))*(IF(L17="",1,IF(L17>0,(L17/100)+1,(100/((-1)*L17))+1))))-1)*(100))))))*10),(((IF(((IF(C17="",1,IF(C17>0,(C17/100)+1,(100/((-1)*C17))+1)))*(IF(D17="",1,IF(D17>0,(D17/100)+1,(100/((-1)*D17))+1)))*(IF(E17="",1,IF(E17>0,(E17/100)+1,(100/((-1)*E17))+1)))*(IF(F17="",1,IF(F17>0,(F17/100)+1,(100/((-1)*F17))+1)))*(IF(G17="",1,IF(G17>0,(G17/100)+1,(100/((-1)*G17))+1)))*(IF(H17="",1,IF(H17>0,(H17/100)+1,(100/((-1)*H17))+1)))*(IF(I17="",1,IF(I17>0,(I17/100)+1,(100/((-1)*I17))+1)))*(IF(J17="",1,IF(J17>0,(J17/100)+1,(100/((-1)*J17))+1)))*(IF(K17="",1,IF(K17>0,(K17/100)+1,(100/((-1)*K17))+1)))*(IF(L17="",1,IF(L17>0,(L17/100)+1,(100/((-1)*L17))+1))))<2,((-100)/(((IF(C17="",1,IF(C17>0,(C17/100)+1,(100/((-1)*C17))+1)))*(IF(D17="",1,IF(D17>0,(D17/100)+1,(100/((-1)*D17))+1)))*(IF(E17="",1,IF(E17>0,(E17/100)+1,(100/((-1)*E17))+1)))*(IF(F17="",1,IF(F17>0,(F17/100)+1,(100/((-1)*F17))+1)))*(IF(G17="",1,IF(G17>0,(G17/100)+1,(100/((-1)*G17))+1)))*(IF(H17="",1,IF(H17>0,(H17/100)+1,(100/((-1)*H17))+1)))*(IF(I17="",1,IF(I17>0,(I17/100)+1,(100/((-1)*I17))+1)))*(IF(J17="",1,IF(J17>0,(J17/100)+1,(100/((-1)*J17))+1)))*(IF(K17="",1,IF(K17>0,(K17/100)+1,(100/((-1)*K17))+1)))*(IF(L17="",1,IF(L17>0,(L17/100)+1,(100/((-1)*L17))+1))))-1)),((((IF(C17="",1,IF(C17>0,(C17/100)+1,(100/((-1)*C17))+1)))*(IF(D17="",1,IF(D17>0,(D17/100)+1,(100/((-1)*D17))+1)))*(IF(E17="",1,IF(E17>0,(E17/100)+1,(100/((-1)*E17))+1)))*(IF(F17="",1,IF(F17>0,(F17/100)+1,(100/((-1)*F17))+1)))*(IF(G17="",1,IF(G17>0,(G17/100)+1,(100/((-1)*G17))+1)))*(IF(H17="",1,IF(H17>0,(H17/100)+1,(100/((-1)*H17))+1)))*(IF(I17="",1,IF(I17>0,(I17/100)+1,(100/((-1)*I17))+1)))*(IF(J17="",1,IF(J17>0,(J17/100)+1,(100/((-1)*J17))+1)))*(IF(K17="",1,IF(K17>0,(K17/100)+1,(100/((-1)*K17))+1)))*(IF(L17="",1,IF(L17>0,(L17/100)+1,(100/((-1)*L17))+1))))-1)*(100))))/100)*10)))
A18: Matchup
A19: Outcome | O19: This Week | P19: Cumulative
A20: W/L | N20: Best Handicapper | O20: =IFERROR(__xludf.DUMMYFUNCTION("IF(OR(COUNTA(C17:L17) = 0, COUNTA(C20:L20) = 0), """", IFERROR(TEXTJOIN("", "", TRUE, FILTER(C14:L14, (C20:L20 = ""W"") * (C17:L17 = MAX(FILTER(C17:L17, C20:L20 = ""W""))))), """"))"),"") | P20: =IFERROR(__xludf.DUMMYFUNCTION("IF(COUNTA(C25:L25) = 0, """", IFERROR(TEXTJOIN("", "", TRUE, FILTER(C14:L14, C25:L25 = MAX(C25:L25))), """"))"),"")
A21: Wins | C21: =IF(OR(C17="",C20=""),"",C8+COUNTIF(C20,"W")) | D21: =IF(OR(D17="",D20=""),"",D8+COUNTIF(D20,"W")) | E21: =IF(OR(E17="",E20=""),"",E8+COUNTIF(E20,"W")) | F21: =IF(OR(F17="",F20=""),"",F8+COUNTIF(F20,"W")) | G21: =IF(OR(G17="",G20=""),"",G8+COUNTIF(G20,"W")) | H21: =IF(OR(H17="",H20=""),"",H8+COUNTIF(H20,"W")) | I21: =IF(OR(I17="",I20=""),"",I8+COUNTIF(I20,"W")) | J21: =IF(OR(J17="",J20=""),"",J8+COUNTIF(J20,"W")) | ... L21: =IF(OR(L17="",L20=""),"",L8+COUNTIF(L20,"W")) | N21: Worst Handicapper | O21: =IFERROR(__xludf.DUMMYFUNCTION("IF(OR(COUNTA(C17:L17) = 0, COUNTA(C20:L20) = 0), """", IFERROR(TEXTJOIN("", "", TRUE, FILTER(C14:L14, (C20:L20 = ""L"") * (C17:L17 = MIN(FILTER(C17:L17, C20:L20 = ""L""))))), """"))"),"") | P21: =IFERROR(__xludf.DUMMYFUNCTION("IF(COUNTA(C25:L25) = 0, """", IFERROR(TEXTJOIN("", "", TRUE, FILTER(C14:L14, C25:L25 = MIN(C25:L25))), """"))"),"")
A22: Losses | C22: =IF(OR(C17="",C20=""),"",C9+COUNTIF(C20,"L")) | D22: =IF(OR(D17="",D20=""),"",D9+COUNTIF(D20,"L")) | E22: =IF(OR(E17="",E20=""),"",E9+COUNTIF(E20,"L")) | F22: =IF(OR(F17="",F20=""),"",F9+COUNTIF(F20,"L")) | G22: =IF(OR(G17="",G20=""),"",G9+COUNTIF(G20,"L")) | H22: =IF(OR(H17="",H20=""),"",H9+COUNTIF(H20,"L")) | I22: =IF(OR(I17="",I20=""),"",I9+COUNTIF(I20,"L")) | J22: =IF(OR(J17="",J20=""),"",J9+COUNTIF(J20,"L")) | ... L22: =IF(OR(L17="",L20=""),"",L9+COUNTIF(L20,"L")) | N22: Ballsiest Bettor | O22: =IFERROR(__xludf.DUMMYFUNCTION("IF(COUNTA(C17:L17) = 0, """", IFERROR(TEXTJOIN("", "", TRUE, FILTER(C14:L14, C17:L17 = MAX(C17:L17))), """"))"),"") | P22: =IFERROR(__xludf.DUMMYFUNCTION("IF(COUNTA(C17:L17) = 0, """", IFERROR(TEXTJOIN("", "", TRUE, FILTER(C14:L14, C24:L24 = MAX(C24:L24))), """"))"),"")
A23: Win % | C23: =IF(OR(C17="",C20=""),"",(C21/(C21+C22))) | D23: =IF(OR(D17="",D20=""),"",(D21/(D21+D22))) | E23: =IF(OR(E17="",E20=""),"",(E21/(E21+E22))) | F23: =IF(OR(F17="",F20=""),"",(F21/(F21+F22))) | G23: =IF(OR(G17="",G20=""),"",(G21/(G21+G22))) | H23: =IF(OR(H17="",H20=""),"",(H21/(H21+H22))) | I23: =IF(OR(I17="",I20=""),"",(I21/(I21+I22))) | J23: =IF(OR(J17="",J20=""),"",(J21/(J21+J22))) | ... L23: =IF(OR(L17="",L20=""),"",(L21/(L21+L22))) | N23: Parlay Pussy | O23: =IFERROR(__xludf.DUMMYFUNCTION("IF(COUNTA(C17:L17) = 0, """", IFERROR(TEXTJOIN("", "", TRUE, FILTER(C14:L14, C17:L17 = MIN(C17:L17))), """"))"),"") | P23: =IFERROR(__xludf.DUMMYFUNCTION("IF(COUNTA(C17:L17) = 0, """", IFERROR(TEXTJOIN("", "", TRUE, FILTER(C14:L14, C24:L24 = MIN(C24:L24))), """"))"),"")
A24: Average Odds | C24: =IF(C17="","",IF(((IF(C17 <0,((-100/C17)+1),((C17/100)+1))+(IF(C11<0,((-100/C11)+1),((C11/100)+1)))*(C8+C9))/(C8+C9+1))<2,(-100/(((IF(C17 <0,((-100/C17)+1),((C17/100)+1))+(IF(C11<0,((-100/C11)+1),((C11/100)+1)))*(C8+C9))/(C8+C9+1))-1)),(((IF(C17 <0,((-100/C17)+1),((C17/100)+1))+(IF(C11<0,((-100/C11)+1),((C11/100)+1)))*(C8+C9))/(C8+C9+1))-1)*100)) | D24: =IF(D17="","",IF(((IF(D17 <0,((-100/D17)+1),((D17/100)+1))+(IF(D11<0,((-100/D11)+1),((D11/100)+1)))*(D8+D9))/(D8+D9+1))<2,(-100/(((IF(D17 <0,((-100/D17)+1),((D17/100)+1))+(IF(D11<0,((-100/D11)+1),((D11/100)+1)))*(D8+D9))/(D8+D9+1))-1)),(((IF(D17 <0,((-100/D17)+1),((D17/100)+1))+(IF(D11<0,((-100/D11)+1),((D11/100)+1)))*(D8+D9))/(D8+D9+1))-1)*100)) | E24: =IF(E17="","",IF(((IF(E17 <0,((-100/E17)+1),((E17/100)+1))+(IF(E11<0,((-100/E11)+1),((E11/100)+1)))*(E8+E9))/(E8+E9+1))<2,(-100/(((IF(E17 <0,((-100/E17)+1),((E17/100)+1))+(IF(E11<0,((-100/E11)+1),((E11/100)+1)))*(E8+E9))/(E8+E9+1))-1)),(((IF(E17 <0,((-100/E17)+1),((E17/100)+1))+(IF(E11<0,((-100/E11)+1),((E11/100)+1)))*(E8+E9))/(E8+E9+1))-1)*100)) | F24: =IF(F17="","",IF(((IF(F17 <0,((-100/F17)+1),((F17/100)+1))+(IF(F11<0,((-100/F11)+1),((F11/100)+1)))*(F8+F9))/(F8+F9+1))<2,(-100/(((IF(F17 <0,((-100/F17)+1),((F17/100)+1))+(IF(F11<0,((-100/F11)+1),((F11/100)+1)))*(F8+F9))/(F8+F9+1))-1)),(((IF(F17 <0,((-100/F17)+1),((F17/100)+1))+(IF(F11<0,((-100/F11)+1),((F11/100)+1)))*(F8+F9))/(F8+F9+1))-1)*100)) | G24: =IF(G17="","",IF(((IF(G17 <0,((-100/G17)+1),((G17/100)+1))+(IF(G11<0,((-100/G11)+1),((G11/100)+1)))*(G8+G9))/(G8+G9+1))<2,(-100/(((IF(G17 <0,((-100/G17)+1),((G17/100)+1))+(IF(G11<0,((-100/G11)+1),((G11/100)+1)))*(G8+G9))/(G8+G9+1))-1)),(((IF(G17 <0,((-100/G17)+1),((G17/100)+1))+(IF(G11<0,((-100/G11)+1),((G11/100)+1)))*(G8+G9))/(G8+G9+1))-1)*100)) | H24: =IF(H17="","",IF(((IF(H17 <0,((-100/H17)+1),((H17/100)+1))+(IF(H11<0,((-100/H11)+1),((H11/100)+1)))*(H8+H9))/(H8+H9+1))<2,(-100/(((IF(H17 <0,((-100/H17)+1),((H17/100)+1))+(IF(H11<0,((-100/H11)+1),((H11/100)+1)))*(H8+H9))/(H8+H9+1))-1)),(((IF(H17 <0,((-100/H17)+1),((H17/100)+1))+(IF(H11<0,((-100/H11)+1),((H11/100)+1)))*(H8+H9))/(H8+H9+1))-1)*100)) | I24: =IF(I17="","",IF(((IF(I17 <0,((-100/I17)+1),((I17/100)+1))+(IF(I11<0,((-100/I11)+1),((I11/100)+1)))*(I8+I9))/(I8+I9+1))<2,(-100/(((IF(I17 <0,((-100/I17)+1),((I17/100)+1))+(IF(I11<0,((-100/I11)+1),((I11/100)+1)))*(I8+I9))/(I8+I9+1))-1)),(((IF(I17 <0,((-100/I17)+1),((I17/100)+1))+(IF(I11<0,((-100/I11)+1),((I11/100)+1)))*(I8+I9))/(I8+I9+1))-1)*100)) | J24: =IF(J17="","",IF(((IF(J17 <0,((-100/J17)+1),((J17/100)+1))+(IF(J11<0,((-100/J11)+1),((J11/100)+1)))*(J8+J9))/(J8+J9+1))<2,(-100/(((IF(J17 <0,((-100/J17)+1),((J17/100)+1))+(IF(J11<0,((-100/J11)+1),((J11/100)+1)))*(J8+J9))/(J8+J9+1))-1)),(((IF(J17 <0,((-100/J17)+1),((J17/100)+1))+(IF(J11<0,((-100/J11)+1),((J11/100)+1)))*(J8+J9))/(J8+J9+1))-1)*100)) | ... L24: =IF(L17="","",IF(((IF(L17 <0,((-100/L17)+1),((L17/100)+1))+(IF(L11<0,((-100/L11)+1),((L11/100)+1)))*(L8+L9))/(L8+L9+1))<2,(-100/(((IF(L17 <0,((-100/L17)+1),((L17/100)+1))+(IF(L11<0,((-100/L11)+1),((L11/100)+1)))*(L8+L9))/(L8+L9+1))-1)),(((IF(L17 <0,((-100/L17)+1),((L17/100)+1))+(IF(L11<0,((-100/L11)+1),((L11/100)+1)))*(L8+L9))/(L8+L9+1))-1)*100))
A25: "If I bet $10 every week" | C25: =IFERROR(__xludf.DUMMYFUNCTION("IF(OR(C16="""",C20=""""),"""",IF(REGEXMATCH(C20,""W""),IF(C17<0,((-100/C17))*10+C12,((C17/100)*10+C12)),-10+C12))"),"") | D25: =IFERROR(__xludf.DUMMYFUNCTION("IF(OR(D16="""",D20=""""),"""",IF(REGEXMATCH(D20,""W""),IF(D17<0,((-100/D17))*10+D12,((D17/100)*10+D12)),-10+D12))"),"") | E25: =IFERROR(__xludf.DUMMYFUNCTION("IF(OR(E16="""",E20=""""),"""",IF(REGEXMATCH(E20,""W""),IF(E17<0,((-100/E17))*10+E12,((E17/100)*10+E12)),-10+E12))"),"") | F25: =IFERROR(__xludf.DUMMYFUNCTION("IF(OR(F16="""",F20=""""),"""",IF(REGEXMATCH(F20,""W""),IF(F17<0,((-100/F17))*10+F12,((F17/100)*10+F12)),-10+F12))"),"") | G25: =IFERROR(__xludf.DUMMYFUNCTION("IF(OR(G16="""",G20=""""),"""",IF(REGEXMATCH(G20,""W""),IF(G17<0,((-100/G17))*10+G12,((G17/100)*10+G12)),-10+G12))"),"") | H25: =IFERROR(__xludf.DUMMYFUNCTION("IF(OR(H16="""",H20=""""),"""",IF(REGEXMATCH(H20,""W""),IF(H17<0,((-100/H17))*10+H12,((H17/100)*10+H12)),-10+H12))"),"") | I25: =IFERROR(__xludf.DUMMYFUNCTION("IF(OR(I16="""",I20=""""),"""",IF(REGEXMATCH(I20,""W""),IF(I17<0,((-100/I17))*10+I12,((I17/100)*10+I12)),-10+I12))"),"") | J25: =IFERROR(__xludf.DUMMYFUNCTION("IF(OR(J16="""",J20=""""),"""",IF(REGEXMATCH(J20,""W""),IF(J17<0,((-100/J17))*10+J12,((J17/100)*10+J12)),-10+J12))"),"") | K25: =IFERROR(__xludf.DUMMYFUNCTION("IF(OR(K16="""",K20=""""),"""",IF(REGEXMATCH(K20,""W""),IF(K17<0,((-100/K17))*10+K12,((K17/100)*10+K12)),-10+K12))"),"") | L25: =IFERROR(__xludf.DUMMYFUNCTION("IF(OR(L16="""",L20=""""),"""",IF(REGEXMATCH(L20,""W""),IF(L17<0,((-100/L17))*10+L12,((L17/100)*10+L12)),-10+L12))"),"") | N25: "If I placed all 10 bets @ $10 each week" | O25: =IFERROR(__xludf.DUMMYFUNCTION("IF(AND(C25="""",AND(D25="""",AND(E25="""",AND(F25="""",AND(G25="""",AND(H25="""",AND(I25="""",AND(J25="""",AND(K25="""",L25=""""))))))))),"""",(IF(C20="""",0,IF(REGEXMATCH(C20,""W""),IF(C17<0,((-100/C17))*10,((C17/100)*10)),-10))+IF(D20="""",0,IF(REGEXMAT"&"CH(D20,""W""),IF(D17<0,((-100/D17))*10,((D17/100)*10)),-10))+IF(E20="""",0,IF(REGEXMATCH(E20,""W""),IF(E17<0,((-100/E17))*10,((E17/100)*10)),-10))+IF(F20="""",0,IF(REGEXMATCH(F20,""W""),IF(F17<0,((-100/F17))*10,((F17/100)*10)),-10))+IF(G20="""",0,IF(REGEX"&"MATCH(G20,""W""),IF(G17<0,((-100/G17))*10,((G17/100)*10)),-10))+IF(H20="""",0,IF(REGEXMATCH(H20,""W""),IF(H17<0,((-100/H17))*10,((H17/100)*10)),-10))+IF(I20="""",0,IF(REGEXMATCH(I20,""W""),IF(I17<0,((-100/I17))*10,((I17/100)*10)),-10))+IF(J20="""",0,IF(RE"&"GEXMATCH(J20,""W""),IF(J17<0,((-100/J17))*10,((J17/100)*10)),-10))+IF(K20="""",0,IF(REGEXMATCH(K20,""W""),IF(K17<0,((-100/K17))*10,((K17/100)*10)),-10))+IF(L20="""",0,IF(REGEXMATCH(L20,""W""),IF(L17<0,((-100/L17))*10,((L17/100)*10)),-10))))"),"") | P25: =IFERROR(__xludf.DUMMYFUNCTION("IF(AND(C25="""",AND(D25="""",AND(E25="""",AND(F25="""",AND(G25="""",AND(H25="""",AND(I25="""",AND(J25="""",AND(K25="""",L25=""""))))))))),"""",(P12+IF(C20="""",0,IF(REGEXMATCH(C20,""W""),IF(C17<0,((-100/C17))*10,((C17/100)*10)),-10))+IF(D20="""",0,IF(REGE"&"XMATCH(D20,""W""),IF(D17<0,((-100/D17))*10,((D17/100)*10)),-10))+IF(E20="""",0,IF(REGEXMATCH(E20,""W""),IF(E17<0,((-100/E17))*10,((E17/100)*10)),-10))+IF(F20="""",0,IF(REGEXMATCH(F20,""W""),IF(F17<0,((-100/F17))*10,((F17/100)*10)),-10))+IF(G20="""",0,IF(R"&"EGEXMATCH(G20,""W""),IF(G17<0,((-100/G17))*10,((G17/100)*10)),-10))+IF(H20="""",0,IF(REGEXMATCH(H20,""W""),IF(H17<0,((-100/H17))*10,((H17/100)*10)),-10))+IF(I20="""",0,IF(REGEXMATCH(I20,""W""),IF(I17<0,((-100/I17))*10,((I17/100)*10)),-10))+IF(J20="""",0,I"&"F(REGEXMATCH(J20,""W""),IF(J17<0,((-100/J17))*10,((J17/100)*10)),-10))+IF(K20="""",0,IF(REGEXMATCH(K20,""W""),IF(K17<0,((-100/K17))*10,((K17/100)*10)),-10))+IF(L20="""",0,IF(REGEXMATCH(L20,""W""),IF(L17<0,((-100/L17))*10,((L17/100)*10)),-10))))"),"")
A27: Week 3 | C27: Austin | D27: Carson | E27: Clayton | F27: Dan | G27: Hunter | H27: Jake | I27: Nick | J27: Tanner | K27: Taylon | L27: Trey | O27: Parlay
A29: Pick | N29: Odds | O29: =IF(AND(C30="",AND(D30="",AND(E30="",AND(F30="",AND(G30="",AND(H30="",AND(I30="",AND(J30="",AND(K30="",L30=""))))))))),"",IF(((IF(C30="",1,IF(C30>0,(C30/100)+1,(100/((-1)*C30))+1)))*(IF(D30="",1,IF(D30>0,(D30/100)+1,(100/((-1)*D30))+1)))*(IF(E30="",1,IF(E30>0,(E30/100)+1,(100/((-1)*E30))+1)))*(IF(F30="",1,IF(F30>0,(F30/100)+1,(100/((-1)*F30))+1)))*(IF(G30="",1,IF(G30>0,(G30/100)+1,(100/((-1)*G30))+1)))*(IF(H30="",1,IF(H30>0,(H30/100)+1,(100/((-1)*H30))+1)))*(IF(I30="",1,IF(I30>0,(I30/100)+1,(100/((-1)*I30))+1)))*(IF(J30="",1,IF(J30>0,(J30/100)+1,(100/((-1)*J30))+1)))*(IF(K30="",1,IF(K30>0,(K30/100)+1,(100/((-1)*K30))+1)))*(IF(L30="",1,IF(L30>0,(L30/100)+1,(100/((-1)*L30))+1))))<2,((-100)/(((IF(C30="",1,IF(C30>0,(C30/100)+1,(100/((-1)*C30))+1)))*(IF(D30="",1,IF(D30>0,(D30/100)+1,(100/((-1)*D30))+1)))*(IF(E30="",1,IF(E30>0,(E30/100)+1,(100/((-1)*E30))+1)))*(IF(F30="",1,IF(F30>0,(F30/100)+1,(100/((-1)*F30))+1)))*(IF(G30="",1,IF(G30>0,(G30/100)+1,(100/((-1)*G30))+1)))*(IF(H30="",1,IF(H30>0,(H30/100)+1,(100/((-1)*H30))+1)))*(IF(I30="",1,IF(I30>0,(I30/100)+1,(100/((-1)*I30))+1)))*(IF(J30="",1,IF(J30>0,(J30/100)+1,(100/((-1)*J30))+1)))*(IF(K30="",1,IF(K30>0,(K30/100)+1,(100/((-1)*K30))+1)))*(IF(L30="",1,IF(L30>0,(L30/100)+1,(100/((-1)*L30))+1))))-1)),((((IF(C30="",1,IF(C30>0,(C30/100)+1,(100/((-1)*C30))+1)))*(IF(D30="",1,IF(D30>0,(D30/100)+1,(100/((-1)*D30))+1)))*(IF(E30="",1,IF(E30>0,(E30/100)+1,(100/((-1)*E30))+1)))*(IF(F30="",1,IF(F30>0,(F30/100)+1,(100/((-1)*F30))+1)))*(IF(G30="",1,IF(G30>0,(G30/100)+1,(100/((-1)*G30))+1)))*(IF(H30="",1,IF(H30>0,(H30/100)+1,(100/((-1)*H30))+1)))*(IF(I30="",1,IF(I30>0,(I30/100)+1,(100/((-1)*I30))+1)))*(IF(J30="",1,IF(J30>0,(J30/100)+1,(100/((-1)*J30))+1)))*(IF(K30="",1,IF(K30>0,(K30/100)+1,(100/((-1)*K30))+1)))*(IF(L30="",1,IF(L30>0,(L30/100)+1,(100/((-1)*L30))+1))))-1)*(100)))) | Q29: *Pick Made For Me*
A30: Odds | M30: 2 | N30: Return | O30: =IF(AND(C30="",AND(D30="",AND(E30="",AND(F30="",AND(G30="",AND(H30="",AND(I30="",AND(J30="",AND(K30="",L30=""))))))))),"",10+IF((IF(((IF(C30="",1,IF(C30>0,(C30/100)+1,(100/((-1)*C30))+1)))*(IF(D30="",1,IF(D30>0,(D30/100)+1,(100/((-1)*D30))+1)))*(IF(E30="",1,IF(E30>0,(E30/100)+1,(100/((-1)*E30))+1)))*(IF(F30="",1,IF(F30>0,(F30/100)+1,(100/((-1)*F30))+1)))*(IF(G30="",1,IF(G30>0,(G30/100)+1,(100/((-1)*G30))+1)))*(IF(H30="",1,IF(H30>0,(H30/100)+1,(100/((-1)*H30))+1)))*(IF(I30="",1,IF(I30>0,(I30/100)+1,(100/((-1)*I30))+1)))*(IF(J30="",1,IF(J30>0,(J30/100)+1,(100/((-1)*J30))+1)))*(IF(K30="",1,IF(K30>0,(K30/100)+1,(100/((-1)*K30))+1)))*(IF(L30="",1,IF(L30>0,(L30/100)+1,(100/((-1)*L30))+1))))<2,((-100)/(((IF(C30="",1,IF(C30>0,(C30/100)+1,(100/((-1)*C30))+1)))*(IF(D30="",1,IF(D30>0,(D30/100)+1,(100/((-1)*D30))+1)))*(IF(E30="",1,IF(E30>0,(E30/100)+1,(100/((-1)*E30))+1)))*(IF(F30="",1,IF(F30>0,(F30/100)+1,(100/((-1)*F30))+1)))*(IF(G30="",1,IF(G30>0,(G30/100)+1,(100/((-1)*G30))+1)))*(IF(H30="",1,IF(H30>0,(H30/100)+1,(100/((-1)*H30))+1)))*(IF(I30="",1,IF(I30>0,(I30/100)+1,(100/((-1)*I30))+1)))*(IF(J30="",1,IF(J30>0,(J30/100)+1,(100/((-1)*J30))+1)))*(IF(K30="",1,IF(K30>0,(K30/100)+1,(100/((-1)*K30))+1)))*(IF(L30="",1,IF(L30>0,(L30/100)+1,(100/((-1)*L30))+1))))-1)),((((IF(C30="",1,IF(C30>0,(C30/100)+1,(100/((-1)*C30))+1)))*(IF(D30="",1,IF(D30>0,(D30/100)+1,(100/((-1)*D30))+1)))*(IF(E30="",1,IF(E30>0,(E30/100)+1,(100/((-1)*E30))+1)))*(IF(F30="",1,IF(F30>0,(F30/100)+1,(100/((-1)*F30))+1)))*(IF(G30="",1,IF(G30>0,(G30/100)+1,(100/((-1)*G30))+1)))*(IF(H30="",1,IF(H30>0,(H30/100)+1,(100/((-1)*H30))+1)))*(IF(I30="",1,IF(I30>0,(I30/100)+1,(100/((-1)*I30))+1)))*(IF(J30="",1,IF(J30>0,(J30/100)+1,(100/((-1)*J30))+1)))*(IF(K30="",1,IF(K30>0,(K30/100)+1,(100/((-1)*K30))+1)))*(IF(L30="",1,IF(L30>0,(L30/100)+1,(100/((-1)*L30))+1))))-1)*(100))))<0,(((-100)/((IF(((IF(C30="",1,IF(C30>0,(C30/100)+1,(100/((-1)*C30))+1)))*(IF(D30="",1,IF(D30>0,(D30/100)+1,(100/((-1)*D30))+1)))*(IF(E30="",1,IF(E30>0,(E30/100)+1,(100/((-1)*E30))+1)))*(IF(F30="",1,IF(F30>0,(F30/100)+1,(100/((-1)*F30))+1)))*(IF(G30="",1,IF(G30>0,(G30/100)+1,(100/((-1)*G30))+1)))*(IF(H30="",1,IF(H30>0,(H30/100)+1,(100/((-1)*H30))+1)))*(IF(I30="",1,IF(I30>0,(I30/100)+1,(100/((-1)*I30))+1)))*(IF(J30="",1,IF(J30>0,(J30/100)+1,(100/((-1)*J30))+1)))*(IF(K30="",1,IF(K30>0,(K30/100)+1,(100/((-1)*K30))+1)))*(IF(L30="",1,IF(L30>0,(L30/100)+1,(100/((-1)*L30))+1))))<2,((-100)/(((IF(C30="",1,IF(C30>0,(C30/100)+1,(100/((-1)*C30))+1)))*(IF(D30="",1,IF(D30>0,(D30/100)+1,(100/((-1)*D30))+1)))*(IF(E30="",1,IF(E30>0,(E30/100)+1,(100/((-1)*E30))+1)))*(IF(F30="",1,IF(F30>0,(F30/100)+1,(100/((-1)*F30))+1)))*(IF(G30="",1,IF(G30>0,(G30/100)+1,(100/((-1)*G30))+1)))*(IF(H30="",1,IF(H30>0,(H30/100)+1,(100/((-1)*H30))+1)))*(IF(I30="",1,IF(I30>0,(I30/100)+1,(100/((-1)*I30))+1)))*(IF(J30="",1,IF(J30>0,(J30/100)+1,(100/((-1)*J30))+1)))*(IF(K30="",1,IF(K30>0,(K30/100)+1,(100/((-1)*K30))+1)))*(IF(L30="",1,IF(L30>0,(L30/100)+1,(100/((-1)*L30))+1))))-1)),((((IF(C30="",1,IF(C30>0,(C30/100)+1,(100/((-1)*C30))+1)))*(IF(D30="",1,IF(D30>0,(D30/100)+1,(100/((-1)*D30))+1)))*(IF(E30="",1,IF(E30>0,(E30/100)+1,(100/((-1)*E30))+1)))*(IF(F30="",1,IF(F30>0,(F30/100)+1,(100/((-1)*F30))+1)))*(IF(G30="",1,IF(G30>0,(G30/100)+1,(100/((-1)*G30))+1)))*(IF(H30="",1,IF(H30>0,(H30/100)+1,(100/((-1)*H30))+1)))*(IF(I30="",1,IF(I30>0,(I30/100)+1,(100/((-1)*I30))+1)))*(IF(J30="",1,IF(J30>0,(J30/100)+1,(100/((-1)*J30))+1)))*(IF(K30="",1,IF(K30>0,(K30/100)+1,(100/((-1)*K30))+1)))*(IF(L30="",1,IF(L30>0,(L30/100)+1,(100/((-1)*L30))+1))))-1)*(100))))))*10),(((IF(((IF(C30="",1,IF(C30>0,(C30/100)+1,(100/((-1)*C30))+1)))*(IF(D30="",1,IF(D30>0,(D30/100)+1,(100/((-1)*D30))+1)))*(IF(E30="",1,IF(E30>0,(E30/100)+1,(100/((-1)*E30))+1)))*(IF(F30="",1,IF(F30>0,(F30/100)+1,(100/((-1)*F30))+1)))*(IF(G30="",1,IF(G30>0,(G30/100)+1,(100/((-1)*G30))+1)))*(IF(H30="",1,IF(H30>0,(H30/100)+1,(100/((-1)*H30))+1)))*(IF(I30="",1,IF(I30>0,(I30/100)+1,(100/((-1)*I30))+1)))*(IF(J30="",1,IF(J30>0,(J30/100)+1,(100/((-1)*J30))+1)))*(IF(K30="",1,IF(K30>0,(K30/100)+1,(100/((-1)*K30))+1)))*(IF(L30="",1,IF(L30>0,(L30/100)+1,(100/((-1)*L30))+1))))<2,((-100)/(((IF(C30="",1,IF(C30>0,(C30/100)+1,(100/((-1)*C30))+1)))*(IF(D30="",1,IF(D30>0,(D30/100)+1,(100/((-1)*D30))+1)))*(IF(E30="",1,IF(E30>0,(E30/100)+1,(100/((-1)*E30))+1)))*(IF(F30="",1,IF(F30>0,(F30/100)+1,(100/((-1)*F30))+1)))*(IF(G30="",1,IF(G30>0,(G30/100)+1,(100/((-1)*G30))+1)))*(IF(H30="",1,IF(H30>0,(H30/100)+1,(100/((-1)*H30))+1)))*(IF(I30="",1,IF(I30>0,(I30/100)+1,(100/((-1)*I30))+1)))*(IF(J30="",1,IF(J30>0,(J30/100)+1,(100/((-1)*J30))+1)))*(IF(K30="",1,IF(K30>0,(K30/100)+1,(100/((-1)*K30))+1)))*(IF(L30="",1,IF(L30>0,(L30/100)+1,(100/((-1)*L30))+1))))-1)),((((IF(C30="",1,IF(C30>0,(C30/100)+1,(100/((-1)*C30))+1)))*(IF(D30="",1,IF(D30>0,(D30/100)+1,(100/((-1)*D30))+1)))*(IF(E30="",1,IF(E30>0,(E30/100)+1,(100/((-1)*E30))+1)))*(IF(F30="",1,IF(F30>0,(F30/100)+1,(100/((-1)*F30))+1)))*(IF(G30="",1,IF(G30>0,(G30/100)+1,(100/((-1)*G30))+1)))*(IF(H30="",1,IF(H30>0,(H30/100)+1,(100/((-1)*H30))+1)))*(IF(I30="",1,IF(I30>0,(I30/100)+1,(100/((-1)*I30))+1)))*(IF(J30="",1,IF(J30>0,(J30/100)+1,(100/((-1)*J30))+1)))*(IF(K30="",1,IF(K30>0,(K30/100)+1,(100/((-1)*K30))+1)))*(IF(L30="",1,IF(L30>0,(L30/100)+1,(100/((-1)*L30))+1))))-1)*(100))))/100)*10)))
A31: Matchup
A32: Outcome | O32: This Week | P32: Cumulative
A33: W/L | N33: Best Handicapper | O33: =IFERROR(__xludf.DUMMYFUNCTION("IF(OR(COUNTA(C30:L30) = 0, COUNTA(C33:L33) = 0), """", IFERROR(TEXTJOIN("", "", TRUE, FILTER(C27:L27, (C33:L33 = ""W"") * (C30:L30 = MAX(FILTER(C30:L30, C33:L33 = ""W""))))), """"))"),"") | P33: =IFERROR(__xludf.DUMMYFUNCTION("IF(COUNTA(C38:L38) = 0, """", IFERROR(TEXTJOIN("", "", TRUE, FILTER(C27:L27, C38:L38 = MAX(C38:L38))), """"))"),"")
A34: Wins | C34: =IF(OR(C30="",C33=""),"",C21+COUNTIF(C33,"W")) | D34: =IF(OR(D30="",D33=""),"",D21+COUNTIF(D33,"W")) | E34: =IF(OR(E30="",E33=""),"",E21+COUNTIF(E33,"W")) | F34: =IF(OR(F30="",F33=""),"",F21+COUNTIF(F33,"W")) | G34: =IF(OR(G30="",G33=""),"",G21+COUNTIF(G33,"W")) | H34: =IF(OR(H30="",H33=""),"",H21+COUNTIF(H33,"W")) | I34: =IF(OR(I30="",I33=""),"",I21+COUNTIF(I33,"W")) | J34: =IF(OR(J30="",J33=""),"",J21+COUNTIF(J33,"W")) | ... L34: =IF(OR(L30="",L33=""),"",L21+COUNTIF(L33,"W")) | N34: Worst Handicapper | O34: =IFERROR(__xludf.DUMMYFUNCTION("IF(OR(COUNTA(C30:L30) = 0, COUNTA(C33:L33) = 0), """", IFERROR(TEXTJOIN("", "", TRUE, FILTER(C27:L27, (C33:L33 = ""L"") * (C30:L30 = MIN(FILTER(C30:L30, C33:L33 = ""L""))))), """"))"),"") | P34: =IFERROR(__xludf.DUMMYFUNCTION("IF(COUNTA(C38:L38) = 0, """", IFERROR(TEXTJOIN("", "", TRUE, FILTER(C27:L27, C38:L38 = MIN(C38:L38))), """"))"),"")
A35: Losses | C35: =IF(OR(C30="",C33=""),"",C22+COUNTIF(C33,"L")) | D35: =IF(OR(D30="",D33=""),"",D22+COUNTIF(D33,"L")) | E35: =IF(OR(E30="",E33=""),"",E22+COUNTIF(E33,"L")) | F35: =IF(OR(F30="",F33=""),"",F22+COUNTIF(F33,"L")) | G35: =IF(OR(G30="",G33=""),"",G22+COUNTIF(G33,"L")) | H35: =IF(OR(H30="",H33=""),"",H22+COUNTIF(H33,"L")) | I35: =IF(OR(I30="",I33=""),"",I22+COUNTIF(I33,"L")) | J35: =IF(OR(J30="",J33=""),"",J22+COUNTIF(J33,"L")) | ... L35: =IF(OR(L30="",L33=""),"",L22+COUNTIF(L33,"L")) | N35: Ballsiest Bettor | O35: =IFERROR(__xludf.DUMMYFUNCTION("IF(COUNTA(C30:L30) = 0, """", IFERROR(TEXTJOIN("", "", TRUE, FILTER(C27:L27, C30:L30 = MAX(C30:L30))), """"))"),"") | P35: =IFERROR(__xludf.DUMMYFUNCTION("IF(COUNTA(C30:L30) = 0, """", IFERROR(TEXTJOIN("", "", TRUE, FILTER(C27:L27, C37:L37 = MAX(C37:L37))), """"))"),"")
A36: Win % | C36: =IF(OR(C30="",C33=""),"",(C34/(C34+C35))) | D36: =IF(OR(D30="",D33=""),"",(D34/(D34+D35))) | E36: =IF(OR(E30="",E33=""),"",(E34/(E34+E35))) | F36: =IF(OR(F30="",F33=""),"",(F34/(F34+F35))) | G36: =IF(OR(G30="",G33=""),"",(G34/(G34+G35))) | H36: =IF(OR(H30="",H33=""),"",(H34/(H34+H35))) | I36: =IF(OR(I30="",I33=""),"",(I34/(I34+I35))) | J36: =IF(OR(J30="",J33=""),"",(J34/(J34+J35))) | ... L36: =IF(OR(L30="",L33=""),"",(L34/(L34+L35))) | N36: Parlay Pussy | O36: =IFERROR(__xludf.DUMMYFUNCTION("IF(COUNTA(C30:L30) = 0, """", IFERROR(TEXTJOIN("", "", TRUE, FILTER(C27:L27, C30:L30 = MIN(C30:L30))), """"))"),"") | P36: =IFERROR(__xludf.DUMMYFUNCTION("IF(COUNTA(C30:L30) = 0, """", IFERROR(TEXTJOIN("", "", TRUE, FILTER(C27:L27, C37:L37 = MIN(C37:L37))), """"))"),"")
A37: Average Odds | C37: =IF(C30="","",IF(((IF(C30 <0,((-100/C30)+1),((C30/100)+1))+(IF(C24<0,((-100/C24)+1),((C24/100)+1)))*(C21+C22))/(C21+C22+1))<2,(-100/(((IF(C30 <0,((-100/C30)+1),((C30/100)+1))+(IF(C24<0,((-100/C24)+1),((C24/100)+1)))*(C21+C22))/(C21+C22+1))-1)),(((IF(C30 <0,((-100/C30)+1),((C30/100)+1))+(IF(C24<0,((-100/C24)+1),((C24/100)+1)))*(C21+C22))/(C21+C22+1))-1)*100)) | D37: =IF(D30="","",IF(((IF(D30 <0,((-100/D30)+1),((D30/100)+1))+(IF(D24<0,((-100/D24)+1),((D24/100)+1)))*(D21+D22))/(D21+D22+1))<2,(-100/(((IF(D30 <0,((-100/D30)+1),((D30/100)+1))+(IF(D24<0,((-100/D24)+1),((D24/100)+1)))*(D21+D22))/(D21+D22+1))-1)),(((IF(D30 <0,((-100/D30)+1),((D30/100)+1))+(IF(D24<0,((-100/D24)+1),((D24/100)+1)))*(D21+D22))/(D21+D22+1))-1)*100)) | E37: =IF(E30="","",IF(((IF(E30 <0,((-100/E30)+1),((E30/100)+1))+(IF(E24<0,((-100/E24)+1),((E24/100)+1)))*(E21+E22))/(E21+E22+1))<2,(-100/(((IF(E30 <0,((-100/E30)+1),((E30/100)+1))+(IF(E24<0,((-100/E24)+1),((E24/100)+1)))*(E21+E22))/(E21+E22+1))-1)),(((IF(E30 <0,((-100/E30)+1),((E30/100)+1))+(IF(E24<0,((-100/E24)+1),((E24/100)+1)))*(E21+E22))/(E21+E22+1))-1)*100)) | F37: =IF(F30="","",IF(((IF(F30 <0,((-100/F30)+1),((F30/100)+1))+(IF(F24<0,((-100/F24)+1),((F24/100)+1)))*(F21+F22))/(F21+F22+1))<2,(-100/(((IF(F30 <0,((-100/F30)+1),((F30/100)+1))+(IF(F24<0,((-100/F24)+1),((F24/100)+1)))*(F21+F22))/(F21+F22+1))-1)),(((IF(F30 <0,((-100/F30)+1),((F30/100)+1))+(IF(F24<0,((-100/F24)+1),((F24/100)+1)))*(F21+F22))/(F21+F22+1))-1)*100)) | G37: =IF(G30="","",IF(((IF(G30 <0,((-100/G30)+1),((G30/100)+1))+(IF(G24<0,((-100/G24)+1),((G24/100)+1)))*(G21+G22))/(G21+G22+1))<2,(-100/(((IF(G30 <0,((-100/G30)+1),((G30/100)+1))+(IF(G24<0,((-100/G24)+1),((G24/100)+1)))*(G21+G22))/(G21+G22+1))-1)),(((IF(G30 <0,((-100/G30)+1),((G30/100)+1))+(IF(G24<0,((-100/G24)+1),((G24/100)+1)))*(G21+G22))/(G21+G22+1))-1)*100)) | H37: =IF(H30="","",IF(((IF(H30 <0,((-100/H30)+1),((H30/100)+1))+(IF(H24<0,((-100/H24)+1),((H24/100)+1)))*(H21+H22))/(H21+H22+1))<2,(-100/(((IF(H30 <0,((-100/H30)+1),((H30/100)+1))+(IF(H24<0,((-100/H24)+1),((H24/100)+1)))*(H21+H22))/(H21+H22+1))-1)),(((IF(H30 <0,((-100/H30)+1),((H30/100)+1))+(IF(H24<0,((-100/H24)+1),((H24/100)+1)))*(H21+H22))/(H21+H22+1))-1)*100)) | I37: =IF(I30="","",IF(((IF(I30 <0,((-100/I30)+1),((I30/100)+1))+(IF(I24<0,((-100/I24)+1),((I24/100)+1)))*(I21+I22))/(I21+I22+1))<2,(-100/(((IF(I30 <0,((-100/I30)+1),((I30/100)+1))+(IF(I24<0,((-100/I24)+1),((I24/100)+1)))*(I21+I22))/(I21+I22+1))-1)),(((IF(I30 <0,((-100/I30)+1),((I30/100)+1))+(IF(I24<0,((-100/I24)+1),((I24/100)+1)))*(I21+I22))/(I21+I22+1))-1)*100)) | J37: =IF(J30="","",IF(((IF(J30 <0,((-100/J30)+1),((J30/100)+1))+(IF(J24<0,((-100/J24)+1),((J24/100)+1)))*(J21+J22))/(J21+J22+1))<2,(-100/(((IF(J30 <0,((-100/J30)+1),((J30/100)+1))+(IF(J24<0,((-100/J24)+1),((J24/100)+1)))*(J21+J22))/(J21+J22+1))-1)),(((IF(J30 <0,((-100/J30)+1),((J30/100)+1))+(IF(J24<0,((-100/J24)+1),((J24/100)+1)))*(J21+J22))/(J21+J22+1))-1)*100)) | ... L37: =IF(L30="","",IF(((IF(L30 <0,((-100/L30)+1),((L30/100)+1))+(IF(L24<0,((-100/L24)+1),((L24/100)+1)))*(L21+L22))/(L21+L22+1))<2,(-100/(((IF(L30 <0,((-100/L30)+1),((L30/100)+1))+(IF(L24<0,((-100/L24)+1),((L24/100)+1)))*(L21+L22))/(L21+L22+1))-1)),(((IF(L30 <0,((-100/L30)+1),((L30/100)+1))+(IF(L24<0,((-100/L24)+1),((L24/100)+1)))*(L21+L22))/(L21+L22+1))-1)*100))
A38: "If I bet $10 every week" | C38: =IFERROR(__xludf.DUMMYFUNCTION("IF(OR(C30="""",C33=""""),"""",IF(REGEXMATCH(C33,""W""),IF(C30<0,((-100/C30))*10+C25,((C30/100)*10+C25)),-10+C25))"),"") | D38: =IFERROR(__xludf.DUMMYFUNCTION("IF(OR(D30="""",D33=""""),"""",IF(REGEXMATCH(D33,""W""),IF(D30<0,((-100/D30))*10+D25,((D30/100)*10+D25)),-10+D25))"),"") | E38: =IFERROR(__xludf.DUMMYFUNCTION("IF(OR(E30="""",E33=""""),"""",IF(REGEXMATCH(E33,""W""),IF(E30<0,((-100/E30))*10+E25,((E30/100)*10+E25)),-10+E25))"),"") | F38: =IFERROR(__xludf.DUMMYFUNCTION("IF(OR(F30="""",F33=""""),"""",IF(REGEXMATCH(F33,""W""),IF(F30<0,((-100/F30))*10+F25,((F30/100)*10+F25)),-10+F25))"),"") | G38: =IFERROR(__xludf.DUMMYFUNCTION("IF(OR(G30="""",G33=""""),"""",IF(REGEXMATCH(G33,""W""),IF(G30<0,((-100/G30))*10+G25,((G30/100)*10+G25)),-10+G25))"),"") | H38: =IFERROR(__xludf.DUMMYFUNCTION("IF(OR(H30="""",H33=""""),"""",IF(REGEXMATCH(H33,""W""),IF(H30<0,((-100/H30))*10+H25,((H30/100)*10+H25)),-10+H25))"),"") | I38: =IFERROR(__xludf.DUMMYFUNCTION("IF(OR(I30="""",I33=""""),"""",IF(REGEXMATCH(I33,""W""),IF(I30<0,((-100/I30))*10+I25,((I30/100)*10+I25)),-10+I25))"),"") | J38: =IFERROR(__xludf.DUMMYFUNCTION("IF(OR(J30="""",J33=""""),"""",IF(REGEXMATCH(J33,""W""),IF(J30<0,((-100/J30))*10+J25,((J30/100)*10+J25)),-10+J25))"),"") | K38: =IFERROR(__xludf.DUMMYFUNCTION("IF(OR(K30="""",K33=""""),"""",IF(REGEXMATCH(K33,""W""),IF(K30<0,((-100/K30))*10+K25,((K30/100)*10+K25)),-10+K25))"),"") | L38: =IFERROR(__xludf.DUMMYFUNCTION("IF(OR(L30="""",L33=""""),"""",IF(REGEXMATCH(L33,""W""),IF(L30<0,((-100/L30))*10+L25,((L30/100)*10+L25)),-10+L25))"),"") | N38: "If I placed all 10 bets @ $10 each week" | O38: =IFERROR(__xludf.DUMMYFUNCTION("IF(AND(C38="""",AND(D38="""",AND(E38="""",AND(F38="""",AND(G38="""",AND(H38="""",AND(I38="""",AND(J38="""",AND(K38="""",L38=""""))))))))),"""",(IF(C33="""",0,IF(REGEXMATCH(C33,""W""),IF(C30<0,((-100/C30))*10,((C30/100)*10)),-10))+IF(D33="""",0,IF(REGEXMAT"&"CH(D33,""W""),IF(D30<0,((-100/D30))*10,((D30/100)*10)),-10))+IF(E33="""",0,IF(REGEXMATCH(E33,""W""),IF(E30<0,((-100/E30))*10,((E30/100)*10)),-10))+IF(F33="""",0,IF(REGEXMATCH(F33,""W""),IF(F30<0,((-100/F30))*10,((F30/100)*10)),-10))+IF(G33="""",0,IF(REGEX"&"MATCH(G33,""W""),IF(G30<0,((-100/G30))*10,((G30/100)*10)),-10))+IF(H33="""",0,IF(REGEXMATCH(H33,""W""),IF(H30<0,((-100/H30))*10,((H30/100)*10)),-10))+IF(I33="""",0,IF(REGEXMATCH(I33,""W""),IF(I30<0,((-100/I30))*10,((I30/100)*10)),-10))+IF(J33="""",0,IF(RE"&"GEXMATCH(J33,""W""),IF(J30<0,((-100/J30))*10,((J30/100)*10)),-10))+IF(K33="""",0,IF(REGEXMATCH(K33,""W""),IF(K30<0,((-100/K30))*10,((K30/100)*10)),-10))+IF(L33="""",0,IF(REGEXMATCH(L33,""W""),IF(L30<0,((-100/L30))*10,((L30/100)*10)),-10))))"),"") | P38: =IFERROR(__xludf.DUMMYFUNCTION("IF(AND(C38="""",AND(D38="""",AND(E38="""",AND(F38="""",AND(G38="""",AND(H38="""",AND(I38="""",AND(J38="""",AND(K38="""",L38=""""))))))))),"""",(P25+IF(C33="""",0,IF(REGEXMATCH(C33,""W""),IF(C30<0,((-100/C30))*10,((C30/100)*10)),-10))+IF(D33="""",0,IF(REGE"&"XMATCH(D33,""W""),IF(D30<0,((-100/D30))*10,((D30/100)*10)),-10))+IF(E33="""",0,IF(REGEXMATCH(E33,""W""),IF(E30<0,((-100/E30))*10,((E30/100)*10)),-10))+IF(F33="""",0,IF(REGEXMATCH(F33,""W""),IF(F30<0,((-100/F30))*10,((F30/100)*10)),-10))+IF(G33="""",0,IF(R"&"EGEXMATCH(G33,""W""),IF(G30<0,((-100/G30))*10,((G30/100)*10)),-10))+IF(H33="""",0,IF(REGEXMATCH(H33,""W""),IF(H30<0,((-100/H30))*10,((H30/100)*10)),-10))+IF(I33="""",0,IF(REGEXMATCH(I33,""W""),IF(I30<0,((-100/I30))*10,((I30/100)*10)),-10))+IF(J33="""",0,I"&"F(REGEXMATCH(J33,""W""),IF(J30<0,((-100/J30))*10,((J30/100)*10)),-10))+IF(K33="""",0,IF(REGEXMATCH(K33,""W""),IF(K30<0,((-100/K30))*10,((K30/100)*10)),-10))+IF(L33="""",0,IF(REGEXMATCH(L33,""W""),IF(L30<0,((-100/L30))*10,((L30/100)*10)),-10))))"),"")
A40: Week 4 | C40: Austin | D40: Carson | E40: Clayton | F40: Dan | G40: Hunter | H40: Jake | I40: Nick | J40: Tanner | K40: Taylon | L40: Trey | O40: Parlay
A42: Pick | N42: Odds | O42: =IF(AND(C43="",AND(D43="",AND(E43="",AND(F43="",AND(G43="",AND(H43="",AND(I43="",AND(J43="",AND(K43="",L43=""))))))))),"",IF(((IF(C43="",1,IF(C43>0,(C43/100)+1,(100/((-1)*C43))+1)))*(IF(D43="",1,IF(D43>0,(D43/100)+1,(100/((-1)*D43))+1)))*(IF(E43="",1,IF(E43>0,(E43/100)+1,(100/((-1)*E43))+1)))*(IF(F43="",1,IF(F43>0,(F43/100)+1,(100/((-1)*F43))+1)))*(IF(G43="",1,IF(G43>0,(G43/100)+1,(100/((-1)*G43))+1)))*(IF(H43="",1,IF(H43>0,(H43/100)+1,(100/((-1)*H43))+1)))*(IF(I43="",1,IF(I43>0,(I43/100)+1,(100/((-1)*I43))+1)))*(IF(J43="",1,IF(J43>0,(J43/100)+1,(100/((-1)*J43))+1)))*(IF(K43="",1,IF(K43>0,(K43/100)+1,(100/((-1)*K43))+1)))*(IF(L43="",1,IF(L43>0,(L43/100)+1,(100/((-1)*L43))+1))))<2,((-100)/(((IF(C43="",1,IF(C43>0,(C43/100)+1,(100/((-1)*C43))+1)))*(IF(D43="",1,IF(D43>0,(D43/100)+1,(100/((-1)*D43))+1)))*(IF(E43="",1,IF(E43>0,(E43/100)+1,(100/((-1)*E43))+1)))*(IF(F43="",1,IF(F43>0,(F43/100)+1,(100/((-1)*F43))+1)))*(IF(G43="",1,IF(G43>0,(G43/100)+1,(100/((-1)*G43))+1)))*(IF(H43="",1,IF(H43>0,(H43/100)+1,(100/((-1)*H43))+1)))*(IF(I43="",1,IF(I43>0,(I43/100)+1,(100/((-1)*I43))+1)))*(IF(J43="",1,IF(J43>0,(J43/100)+1,(100/((-1)*J43))+1)))*(IF(K43="",1,IF(K43>0,(K43/100)+1,(100/((-1)*K43))+1)))*(IF(L43="",1,IF(L43>0,(L43/100)+1,(100/((-1)*L43))+1))))-1)),((((IF(C43="",1,IF(C43>0,(C43/100)+1,(100/((-1)*C43))+1)))*(IF(D43="",1,IF(D43>0,(D43/100)+1,(100/((-1)*D43))+1)))*(IF(E43="",1,IF(E43>0,(E43/100)+1,(100/((-1)*E43))+1)))*(IF(F43="",1,IF(F43>0,(F43/100)+1,(100/((-1)*F43))+1)))*(IF(G43="",1,IF(G43>0,(G43/100)+1,(100/((-1)*G43))+1)))*(IF(H43="",1,IF(H43>0,(H43/100)+1,(100/((-1)*H43))+1)))*(IF(I43="",1,IF(I43>0,(I43/100)+1,(100/((-1)*I43))+1)))*(IF(J43="",1,IF(J43>0,(J43/100)+1,(100/((-1)*J43))+1)))*(IF(K43="",1,IF(K43>0,(K43/100)+1,(100/((-1)*K43))+1)))*(IF(L43="",1,IF(L43>0,(L43/100)+1,(100/((-1)*L43))+1))))-1)*(100)))) | Q42: *Pick Made For Me*
A43: Odds | M43: 3 | N43: Return | O43: =IF(AND(C43="",AND(D43="",AND(E43="",AND(F43="",AND(G43="",AND(H43="",AND(I43="",AND(J43="",AND(K43="",L43=""))))))))),"",10+IF((IF(((IF(C43="",1,IF(C43>0,(C43/100)+1,(100/((-1)*C43))+1)))*(IF(D43="",1,IF(D43>0,(D43/100)+1,(100/((-1)*D43))+1)))*(IF(E43="",1,IF(E43>0,(E43/100)+1,(100/((-1)*E43))+1)))*(IF(F43="",1,IF(F43>0,(F43/100)+1,(100/((-1)*F43))+1)))*(IF(G43="",1,IF(G43>0,(G43/100)+1,(100/((-1)*G43))+1)))*(IF(H43="",1,IF(H43>0,(H43/100)+1,(100/((-1)*H43))+1)))*(IF(I43="",1,IF(I43>0,(I43/100)+1,(100/((-1)*I43))+1)))*(IF(J43="",1,IF(J43>0,(J43/100)+1,(100/((-1)*J43))+1)))*(IF(K43="",1,IF(K43>0,(K43/100)+1,(100/((-1)*K43))+1)))*(IF(L43="",1,IF(L43>0,(L43/100)+1,(100/((-1)*L43))+1))))<2,((-100)/(((IF(C43="",1,IF(C43>0,(C43/100)+1,(100/((-1)*C43))+1)))*(IF(D43="",1,IF(D43>0,(D43/100)+1,(100/((-1)*D43))+1)))*(IF(E43="",1,IF(E43>0,(E43/100)+1,(100/((-1)*E43))+1)))*(IF(F43="",1,IF(F43>0,(F43/100)+1,(100/((-1)*F43))+1)))*(IF(G43="",1,IF(G43>0,(G43/100)+1,(100/((-1)*G43))+1)))*(IF(H43="",1,IF(H43>0,(H43/100)+1,(100/((-1)*H43))+1)))*(IF(I43="",1,IF(I43>0,(I43/100)+1,(100/((-1)*I43))+1)))*(IF(J43="",1,IF(J43>0,(J43/100)+1,(100/((-1)*J43))+1)))*(IF(K43="",1,IF(K43>0,(K43/100)+1,(100/((-1)*K43))+1)))*(IF(L43="",1,IF(L43>0,(L43/100)+1,(100/((-1)*L43))+1))))-1)),((((IF(C43="",1,IF(C43>0,(C43/100)+1,(100/((-1)*C43))+1)))*(IF(D43="",1,IF(D43>0,(D43/100)+1,(100/((-1)*D43))+1)))*(IF(E43="",1,IF(E43>0,(E43/100)+1,(100/((-1)*E43))+1)))*(IF(F43="",1,IF(F43>0,(F43/100)+1,(100/((-1)*F43))+1)))*(IF(G43="",1,IF(G43>0,(G43/100)+1,(100/((-1)*G43))+1)))*(IF(H43="",1,IF(H43>0,(H43/100)+1,(100/((-1)*H43))+1)))*(IF(I43="",1,IF(I43>0,(I43/100)+1,(100/((-1)*I43))+1)))*(IF(J43="",1,IF(J43>0,(J43/100)+1,(100/((-1)*J43))+1)))*(IF(K43="",1,IF(K43>0,(K43/100)+1,(100/((-1)*K43))+1)))*(IF(L43="",1,IF(L43>0,(L43/100)+1,(100/((-1)*L43))+1))))-1)*(100))))<0,(((-100)/((IF(((IF(C43="",1,IF(C43>0,(C43/100)+1,(100/((-1)*C43))+1)))*(IF(D43="",1,IF(D43>0,(D43/100)+1,(100/((-1)*D43))+1)))*(IF(E43="",1,IF(E43>0,(E43/100)+1,(100/((-1)*E43))+1)))*(IF(F43="",1,IF(F43>0,(F43/100)+1,(100/((-1)*F43))+1)))*(IF(G43="",1,IF(G43>0,(G43/100)+1,(100/((-1)*G43))+1)))*(IF(H43="",1,IF(H43>0,(H43/100)+1,(100/((-1)*H43))+1)))*(IF(I43="",1,IF(I43>0,(I43/100)+1,(100/((-1)*I43))+1)))*(IF(J43="",1,IF(J43>0,(J43/100)+1,(100/((-1)*J43))+1)))*(IF(K43="",1,IF(K43>0,(K43/100)+1,(100/((-1)*K43))+1)))*(IF(L43="",1,IF(L43>0,(L43/100)+1,(100/((-1)*L43))+1))))<2,((-100)/(((IF(C43="",1,IF(C43>0,(C43/100)+1,(100/((-1)*C43))+1)))*(IF(D43="",1,IF(D43>0,(D43/100)+1,(100/((-1)*D43))+1)))*(IF(E43="",1,IF(E43>0,(E43/100)+1,(100/((-1)*E43))+1)))*(IF(F43="",1,IF(F43>0,(F43/100)+1,(100/((-1)*F43))+1)))*(IF(G43="",1,IF(G43>0,(G43/100)+1,(100/((-1)*G43))+1)))*(IF(H43="",1,IF(H43>0,(H43/100)+1,(100/((-1)*H43))+1)))*(IF(I43="",1,IF(I43>0,(I43/100)+1,(100/((-1)*I43))+1)))*(IF(J43="",1,IF(J43>0,(J43/100)+1,(100/((-1)*J43))+1)))*(IF(K43="",1,IF(K43>0,(K43/100)+1,(100/((-1)*K43))+1)))*(IF(L43="",1,IF(L43>0,(L43/100)+1,(100/((-1)*L43))+1))))-1)),((((IF(C43="",1,IF(C43>0,(C43/100)+1,(100/((-1)*C43))+1)))*(IF(D43="",1,IF(D43>0,(D43/100)+1,(100/((-1)*D43))+1)))*(IF(E43="",1,IF(E43>0,(E43/100)+1,(100/((-1)*E43))+1)))*(IF(F43="",1,IF(F43>0,(F43/100)+1,(100/((-1)*F43))+1)))*(IF(G43="",1,IF(G43>0,(G43/100)+1,(100/((-1)*G43))+1)))*(IF(H43="",1,IF(H43>0,(H43/100)+1,(100/((-1)*H43))+1)))*(IF(I43="",1,IF(I43>0,(I43/100)+1,(100/((-1)*I43))+1)))*(IF(J43="",1,IF(J43>0,(J43/100)+1,(100/((-1)*J43))+1)))*(IF(K43="",1,IF(K43>0,(K43/100)+1,(100/((-1)*K43))+1)))*(IF(L43="",1,IF(L43>0,(L43/100)+1,(100/((-1)*L43))+1))))-1)*(100))))))*10),(((IF(((IF(C43="",1,IF(C43>0,(C43/100)+1,(100/((-1)*C43))+1)))*(IF(D43="",1,IF(D43>0,(D43/100)+1,(100/((-1)*D43))+1)))*(IF(E43="",1,IF(E43>0,(E43/100)+1,(100/((-1)*E43))+1)))*(IF(F43="",1,IF(F43>0,(F43/100)+1,(100/((-1)*F43))+1)))*(IF(G43="",1,IF(G43>0,(G43/100)+1,(100/((-1)*G43))+1)))*(IF(H43="",1,IF(H43>0,(H43/100)+1,(100/((-1)*H43))+1)))*(IF(I43="",1,IF(I43>0,(I43/100)+1,(100/((-1)*I43))+1)))*(IF(J43="",1,IF(J43>0,(J43/100)+1,(100/((-1)*J43))+1)))*(IF(K43="",1,IF(K43>0,(K43/100)+1,(100/((-1)*K43))+1)))*(IF(L43="",1,IF(L43>0,(L43/100)+1,(100/((-1)*L43))+1))))<2,((-100)/(((IF(C43="",1,IF(C43>0,(C43/100)+1,(100/((-1)*C43))+1)))*(IF(D43="",1,IF(D43>0,(D43/100)+1,(100/((-1)*D43))+1)))*(IF(E43="",1,IF(E43>0,(E43/100)+1,(100/((-1)*E43))+1)))*(IF(F43="",1,IF(F43>0,(F43/100)+1,(100/((-1)*F43))+1)))*(IF(G43="",1,IF(G43>0,(G43/100)+1,(100/((-1)*G43))+1)))*(IF(H43="",1,IF(H43>0,(H43/100)+1,(100/((-1)*H43))+1)))*(IF(I43="",1,IF(I43>0,(I43/100)+1,(100/((-1)*I43))+1)))*(IF(J43="",1,IF(J43>0,(J43/100)+1,(100/((-1)*J43))+1)))*(IF(K43="",1,IF(K43>0,(K43/100)+1,(100/((-1)*K43))+1)))*(IF(L43="",1,IF(L43>0,(L43/100)+1,(100/((-1)*L43))+1))))-1)),((((IF(C43="",1,IF(C43>0,(C43/100)+1,(100/((-1)*C43))+1)))*(IF(D43="",1,IF(D43>0,(D43/100)+1,(100/((-1)*D43))+1)))*(IF(E43="",1,IF(E43>0,(E43/100)+1,(100/((-1)*E43))+1)))*(IF(F43="",1,IF(F43>0,(F43/100)+1,(100/((-1)*F43))+1)))*(IF(G43="",1,IF(G43>0,(G43/100)+1,(100/((-1)*G43))+1)))*(IF(H43="",1,IF(H43>0,(H43/100)+1,(100/((-1)*H43))+1)))*(IF(I43="",1,IF(I43>0,(I43/100)+1,(100/((-1)*I43))+1)))*(IF(J43="",1,IF(J43>0,(J43/100)+1,(100/((-1)*J43))+1)))*(IF(K43="",1,IF(K43>0,(K43/100)+1,(100/((-1)*K43))+1)))*(IF(L43="",1,IF(L43>0,(L43/100)+1,(100/((-1)*L43))+1))))-1)*(100))))/100)*10)))
A44: Matchup
A45: Outcome | O45: This Week | P45: Cumulative
A46: W/L | N46: Best Handicapper | O46: =IFERROR(__xludf.DUMMYFUNCTION("IF(OR(COUNTA(C43:L43) = 0, COUNTA(C46:L46) = 0), """", IFERROR(TEXTJOIN("", "", TRUE, FILTER(C40:L40, (C46:L46 = ""W"") * (C43:L43 = MAX(FILTER(C43:L43, C46:L46 = ""W""))))), """"))"),"") | P46: =IFERROR(__xludf.DUMMYFUNCTION("IF(COUNTA(C51:L51) = 0, """", IFERROR(TEXTJOIN("", "", TRUE, FILTER(C40:L40, C51:L51 = MAX(C51:L51))), """"))"),"")
A47: Wins | C47: =IF(OR(C43="",C46=""),"",C34+COUNTIF(C46,"W")) | D47: =IF(OR(D43="",D46=""),"",D34+COUNTIF(D46,"W")) | E47: =IF(OR(E43="",E46=""),"",E34+COUNTIF(E46,"W")) | F47: =IF(OR(F43="",F46=""),"",F34+COUNTIF(F46,"W")) | G47: =IF(OR(G43="",G46=""),"",G34+COUNTIF(G46,"W")) | H47: =IF(OR(H43="",H46=""),"",H34+COUNTIF(H46,"W")) | I47: =IF(OR(I43="",I46=""),"",I34+COUNTIF(I46,"W")) | J47: =IF(OR(J43="",J46=""),"",J34+COUNTIF(J46,"W")) | ... L47: =IF(OR(L43="",L46=""),"",L34+COUNTIF(L46,"W")) | N47: Worst Handicapper | O47: =IFERROR(__xludf.DUMMYFUNCTION("IF(OR(COUNTA(C43:L43) = 0, COUNTA(C46:L46) = 0), """", IFERROR(TEXTJOIN("", "", TRUE, FILTER(C40:L40, (C46:L46 = ""L"") * (C43:L43 = MIN(FILTER(C43:L43, C46:L46 = ""L""))))), """"))"),"") | P47: =IFERROR(__xludf.DUMMYFUNCTION("IF(COUNTA(C51:L51) = 0, """", IFERROR(TEXTJOIN("", "", TRUE, FILTER(C40:L40, C51:L51 = MIN(C51:L51))), """"))"),"")
...

Sheet 2025
A1: Week 1 | C1: Austin | D1: Carson | E1: Clayton | F1: Dan | G1: Hunter | H1: Jake | I1: Nick | J1: Tanner | K1: Taylon | L1: Trey | O1: Parlay
A3: Pick | C3: Commanders -3.5 | D3: Steelers Moneyline | E3: Panthers +3.5 | F3: Cardinals -6.5 | G3: B. Bowers 76+ Rec. Yards | H3: Texans +2.5 | I3: J. Burrow Over 7.5 Rush Yards | J3: Broncos -6.5 | K3: Seahawks Under 20.5 Points | L3: J. Gibbs ATD | N3: Odds | O3: =IF(AND(C4="",AND(D4="",AND(E4="",AND(F4="",AND(G4="",AND(H4="",AND(I4="",AND(J4="",AND(K4="",L4=""))))))))),"",IF(((IF(C4="",1,IF(C4>0,(C4/100)+1,(100/((-1)*C4))+1)))*(IF(D4="",1,IF(D4>0,(D4/100)+1,(100/((-1)*D4))+1)))*(IF(E4="",1,IF(E4>0,(E4/100)+1,(100/((-1)*E4))+1)))*(IF(F4="",1,IF(F4>0,(F4/100)+1,(100/((-1)*F4))+1)))*(IF(G4="",1,IF(G4>0,(G4/100)+1,(100/((-1)*G4))+1)))*(IF(H4="",1,IF(H4>0,(H4/100)+1,(100/((-1)*H4))+1)))*(IF(I4="",1,IF(I4>0,(I4/100)+1,(100/((-1)*I4))+1)))*(IF(J4="",1,IF(J4>0,(J4/100)+1,(100/((-1)*J4))+1)))*(IF(K4="",1,IF(K4>0,(K4/100)+1,(100/((-1)*K4))+1)))*(IF(L4="",1,IF(L4>0,(L4/100)+1,(100/((-1)*L4))+1))))<2,((-100)/(((IF(C4="",1,IF(C4>0,(C4/100)+1,(100/((-1)*C4))+1)))*(IF(D4="",1,IF(D4>0,(D4/100)+1,(100/((-1)*D4))+1)))*(IF(E4="",1,IF(E4>0,(E4/100)+1,(100/((-1)*E4))+1)))*(IF(F4="",1,IF(F4>0,(F4/100)+1,(100/((-1)*F4))+1)))*(IF(G4="",1,IF(G4>0,(G4/100)+1,(100/((-1)*G4))+1)))*(IF(H4="",1,IF(H4>0,(H4/100)+1,(100/((-1)*H4))+1)))*(IF(I4="",1,IF(I4>0,(I4/100)+1,(100/((-1)*I4))+1)))*(IF(J4="",1,IF(J4>0,(J4/100)+1,(100/((-1)*J4))+1)))*(IF(K4="",1,IF(K4>0,(K4/100)+1,(100/((-1)*K4))+1)))*(IF(L4="",1,IF(L4>0,(L4/100)+1,(100/((-1)*L4))+1))))-1)),((((IF(C4="",1,IF(C4>0,(C4/100)+1,(100/((-1)*C4))+1)))*(IF(D4="",1,IF(D4>0,(D4/100)+1,(100/((-1)*D4))+1)))*(IF(E4="",1,IF(E4>0,(E4/100)+1,(100/((-1)*E4))+1)))*(IF(F4="",1,IF(F4>0,(F4/100)+1,(100/((-1)*F4))+1)))*(IF(G4="",1,IF(G4>0,(G4/100)+1,(100/((-1)*G4))+1)))*(IF(H4="",1,IF(H4>0,(H4/100)+1,(100/((-1)*H4))+1)))*(IF(I4="",1,IF(I4>0,(I4/100)+1,(100/((-1)*I4))+1)))*(IF(J4="",1,IF(J4>0,(J4/100)+1,(100/((-1)*J4))+1)))*(IF(K4="",1,IF(K4>0,(K4/100)+1,(100/((-1)*K4))+1)))*(IF(L4="",1,IF(L4>0,(L4/100)+1,(100/((-1)*L4))+1))))-1)*(100)))) -> 41962.665 | Q3: *Pick Made For Me*
